Workbook
Name FirstYear: Inputs!$D$9
Name GuideHigh: Inputs!$E$68
Name GuideLow: Inputs!$D$68
Name LastActual: Inputs!$D$10
Name ModelChecks: Cover!$G$29
Name Scenario: Outputs!$D$5
Name ScenarioList: Inputs!$D$131:$D$133
Name ScenarioName: Inputs!$D$135
Name SharesOut: Inputs!$D$15
Name TaxRate: Inputs!$D$12
Name TGR: Outputs!$D$9
Name ValDate: Inputs!$D$11
Name WACC: Outputs!$D$8

Sheet Cover
B1: Kofola ČeskoSlovensko a.s.
B3: 3-statement model, DCF and comparables | E3: Scenario
B4: Prepared by Matúš Balko | Valuation date 30.06.2026 | CZK m unless stated
B6: Contents
B7: Dashboard | C7: One-page summary: company overview, valuation and key charts
B8: Outputs | C8: Scenario switch, DCF summary, football field, scenario and sensitivity tables
B9: Inputs | C9: General inputs, scenario drivers, WACC build
B10: Model | C10: Schedules, three statements, FCF bridge, DCF
B11: Comps | C11: Trading comparables and precedent transactions
B12: Hist | C12: Source data from the annual and interim reports
B14: Conventions
B15: Hardcoded input or source figure | C15: 1,234.5
B16: Formula, including links to other sheets | C16: 1,234.5
B17: Scenario: pick Base / Upside / Downside case in the drop-down on Cover, Outputs or Inputs
B18: Costs and cash outflows are negative, subtotals are plain sums
B19: A = actual, F = forecast, fiscal year = calendar year
B20: Check rows are rounded to 0.1 (source figures are to the nearest CZK thousand)
B22: Model checks
B23: Check | F23: Difference | G23: Status
B24: EBITDA vs reported | F24: =SUMPRODUCT(ABS(Model!D39:L39)) -> 0 | G24: =IFERROR(IF(F24=0,"OK","ERROR"),"ERROR") -> OK
B25: Net profit vs reported | F25: =SUMPRODUCT(ABS(Model!D71:L71)) -> 0 | G25: =IFERROR(IF(F25=0,"OK","ERROR"),"ERROR") -> OK
B26: Balance sheet balances | F26: =SUMPRODUCT(ABS(Model!D106:L106)) -> 0 | G26: =IFERROR(IF(F26=0,"OK","ERROR"),"ERROR") -> OK
B27: Closing cash vs balance sheet | F27: =SUMPRODUCT(ABS(Model!D144:L144)) -> 0 | G27: =IFERROR(IF(F27=0,"OK","ERROR"),"ERROR") -> OK
B28: DCF: sum of discounted cash flows vs XNPV (both methods) | F28: =ROUND(ABS(Model!D286-Model!D287)+ABS(Model!D325-Model!D326),1) -> 0 | G28: =IFERROR(IF(F28=0,"OK","ERROR"),"ERROR") -> OK
B29: All checks | G29: =IF(COUNTIF(G24:G28,"OK")=ROWS(G24:G28),"OK","ERROR") -> OK

Sheet Dashboard
B1: Kofola ČeskoSlovensko | Dashboard
B2: ="CZK m unless stated | Valuation date 30.06.2026 | Active scenario: "&ScenarioName -> CZK m unless stated | Valuation date 30.06.2026 | Active scenario: Base case
B4: Company overview | P4: Data: company overview
B6: Kofola ČeskoSlovensko a.s. (PSE: KOFOL) | F6: ="Share price at 30.06.2026: CZK "&FIXED(Q9,0) -> Share price at 30.06.2026: CZK 493 | N6: ="Market capitalisation: CZK "&SUBSTITUTE(FIXED(Q11/1000,1,TRUE),",",".")&"bn" -> Market capitalisation: CZK 10.5bn | P6: Company | Q6: Kofola ČeskoSlovensko a.s.
P7: Ticker | Q7: KOFOL (Prague Stock Exchange)
B8: Central European producer of soft drinks, mineral waters, syrups, fresh juices and teas. Beer since the Pivovary Zubr deal closed in March 2024. | P8: Valuation date | Q8: =ValDate -> 46203
B9: Own brands include Kofola, Vinea, Rajec, Radenska, Studenac, Jupí, Semtex, UGO and Leros, plus the beers Zubr, Holba and Litovel. | P9: Share price at 30.06.2026 (CZK) | Q9: =Inputs!D113 -> 493
B10: Fourteen plants in the Czech Republic, Slovakia, Slovenia, Croatia and Poland, selling through retail, HoReCa and impulse channels. | P10: Shares outstanding (m) | Q10: =SharesOut -> 21.333731
B11: Four reporting segments: CzechoSlovakia, Adriatic, Fresh & Herbs, and Beers & Ciders. | P11: Market capitalisation (CZK m) | Q11: =Inputs!D114 -> 10517.529
B12: ="FY2025A revenue CZK "&SUBSTITUTE(FIXED(Model!G16/1000,1,TRUE),",",".")&"bn, adjusted EBITDA CZK "&SUBSTITUTE(FIXED(Model!G38/1000,1,TRUE),",",".")&"bn ("&SUBSTITUTE(FIXED(Model!G48*100,1,TRUE),",",".")&"% margin), net debt / adjusted EBITDA "&SUBSTITUTE(FIXED(Model!G221,1,TRUE),",",".")&"x, dividend CZK "&FIXED(Model!G77,0)&" per share." -> FY2025A revenue CZK 10.8bn, adjusted EBITDA CZK 1.8bn (16.9% margin), net debt / adjusted EBITDA 3.0x, dividend CZK 21 per share. | P12: Net debt at 30.06.2026 (CZK m) | Q12: =Inputs!D115 -> 6441.73
B13: ="2026 EBITDA guidance of CZK "&SUBSTITUTE(FIXED(GuideLow/1000,1,TRUE),",",".")&" to "&SUBSTITUTE(FIXED(GuideHigh/1000,1,TRUE),",",".")&"bn. Acquisitions in H1 2026: Nobilis Tilia (natural cosmetics) and Alta Fermentación (Latin America)." -> 2026 EBITDA guidance of CZK 1.8 to 1.9bn. Acquisitions in H1 2026: Nobilis Tilia (natural cosmetics) and Alta Fermentación (Latin America). | P13: EV / LTM adjusted EBITDA, bonus-normalised (x) | Q13: =Comps!G38 -> 9.787734
B14: ="DCF value per share CZK "&FIXED(Q15,0)&" (perpetuity growth) and CZK "&FIXED(Q16,0)&" (exit multiple), against a share price of CZK "&FIXED(Q9,0)&" at 30.06.2026." -> DCF value per share CZK 416 (perpetuity growth) and CZK 512 (exit multiple), against a share price of CZK 493 at 30.06.2026. | P14: P / E on LTM adjusted net profit, bonus-normalised (x) | Q14: =Comps!H38 -> 22.807018
B15: After 30.06.2026, not in the valuation: 52% of COKAFE (August) and the Bohemia Healing Marienbad Waters business for CZK 414m (September). | P15: DCF value per share, perpetuity growth (CZK) | Q15: =Outputs!D26 -> 415.70732
B16: Also signed in September 2026: 51% of Chachar catering (Ostrava-based chain of 43 pubs, closing by the end of 2026). | P16: DCF value per share, exit multiple (CZK) | Q16: =Outputs!E26 -> 511.87859
B17: Share price, last 52 weeks (CZK) | I17: Football field (CZK per share) | P17: Average of base values, football field (CZK) | Q17: =Outputs!G46 -> 459.72115
P19: Data: football field (CZK per share)
P20: Method | Q20: Low | R20: High | S20: Base
P21: =Outputs!B40 -> DCF (perpetuity growth) | Q21: =Outputs!D40 -> 292.45327 | R21: =Outputs!F40 -> 607.77376 | S21: =Outputs!G40 -> 415.70732
P22: =Outputs!B41 -> DCF (exit multiple) | Q22: =Outputs!D41 -> 420.92545 | R22: =Outputs!F41 -> 606.47851 | S22: =Outputs!G41 -> 511.87859
P23: =Outputs!B42 -> Trading comps (EV / EBITDA) | Q23: =Outputs!D42 -> 200.30553 | R23: =Outputs!F42 -> 632.2358 | S23: =Outputs!G42 -> 451.57755
P24: =Outputs!B43 -> Trading comps (P / E) | Q24: =Outputs!D43 -> 216.70021 | R24: =Outputs!F43 -> 421.90739 | S24: =Outputs!G43 -> 292.33561
P25: =Outputs!B44 -> Precedent transactions (EV / EBITDA) | Q25: =Outputs!D44 -> 577.18758 | R25: =Outputs!F44 -> 985.89619 | S25: =Outputs!G44 -> 740.66789
P26: =Outputs!B45 -> 52-week trading range | Q26: =Outputs!D45 -> 450 | R26: =Outputs!F45 -> 546 | S26: =Outputs!G45 -> 493
P27: ="Average of base values (CZK "&FIXED(S27,0)&")" -> Average of base values (CZK 460) | S27: =Outputs!G46 -> 459.72115
P29: Data: financials
P30: CZK m unless stated | Q30: =Model!D$4&Model!D$6 -> 2022A | R30: =Model!E$4&Model!E$6 -> 2023A | S30: =Model!F$4&Model!F$6 -> 2024A | T30: =Model!G$4&Model!G$6 -> 2025A | U30: =Model!H$4&Model!H$6 -> 2026F | V30: =Model!I$4&Model!I$6 -> 2027F | W30: =Model!J$4&Model!J$6 -> 2028F | X30: =Model!K$4&Model!K$6 -> 2029F | Y30: =Model!L$4&Model!L$6 -> 2030F
P31: Revenue growth | R31: =Model!E24 -> 0.10346535 | S31: =Model!F24 -> 0.27523839 | T31: =Model!G24 -> -0.029563832 | U31: =Model!H24 -> 0.069292779 | V31: =Model!I24 -> 0.044027053 | W31: =Model!J24 -> 0.03921314 | X31: =Model!K24 -> 0.034998888 | Y31: =Model!L24 -> 0.032953725
P32: Adjusted EBITDA margin | Q32: =Model!D48 -> 0.14100203 | R32: =Model!E48 -> 0.1442335 | S32: =Model!F48 -> 0.16702769 | T32: =Model!G48 -> 0.16890344 | U32: =Model!H48 -> 0.164 | V32: =Model!I48 -> 0.161 | W32: =Model!J48 -> 0.162 | X32: =Model!K48 -> 0.163 | Y32: =Model!L48 -> 0.163
P34: CzechoSlovakia | Q34: =Model!D11 -> 5735.854 | R34: =Model!E11 -> 6314.707 | S34: =Model!F11 -> 7015.597 | T34: =Model!G11 -> 6542.522 | U34: =Model!H11 -> 7196.7742 | V34: =Model!I11 -> 7484.6452 | W34: =Model!J11 -> 7746.6077 | X34: =Model!K11 -> 7979.006 | Y34: =Model!L11 -> 8218.3762
B35: Revenue by segment (CZK m) and revenue growth | I35: Adjusted EBITDA, free cash flow and dividends (CZK m) | P35: Adriatic | Q35: =Model!D12 -> 1413.483 | R35: =Model!E12 -> 1514.892 | S35: =Model!F12 -> 1683.172 | T35: =Model!G12 -> 1652.173 | U35: =Model!H12 -> 1685.2165 | V35: =Model!I12 -> 1735.773 | W35: =Model!J12 -> 1787.8461 | X35: =Model!K12 -> 1841.4815 | Y35: =Model!L12 -> 1887.5186
P36: Fresh & Herbs | Q36: =Model!D13 -> 876.848 | R36: =Model!E13 -> 1026.918 | S36: =Model!F13 -> 1230.533 | T36: =Model!G13 -> 1420.817 | U36: =Model!H13 -> 1676.5641 | V36: =Model!I13 -> 1844.2205 | W36: =Model!J13 -> 1991.7581 | X36: =Model!K13 -> 2131.1812 | Y36: =Model!L13 -> 2259.052
P37: Beers & Ciders | Q37: =Model!D14 -> 0 | R37: =Model!E14 -> 0 | S37: =Model!F14 -> 1400.375 | T37: =Model!G14 -> 1479.289 | U37: =Model!H14 -> 1420.1174 | V37: =Model!I14 -> 1441.4192 | W37: =Model!J14 -> 1470.2476 | X37: =Model!K14 -> 1499.6525 | Y37: =Model!L14 -> 1529.6456
P38: Consolidation adjustments | Q38: =Model!D15 -> -150.901 | R38: =Model!E15 -> -166.414 | S38: =Model!F15 -> -247.724 | T38: =Model!G15 -> -340.473 | U38: =Model!H15 -> -479.14689 | V38: =Model!I15 -> -500.24231 | W38: =Model!J15 -> -519.85838 | X38: =Model!K15 -> -538.05285 | Y38: =Model!L15 -> -555.78369
P39: Revenue | Q39: =Model!D16 -> 7875.284 | R39: =Model!E16 -> 8690.103 | S39: =Model!F16 -> 11081.953 | T39: =Model!G16 -> 10754.328 | U39: =Model!H16 -> 11499.525 | V39: =Model!I16 -> 12005.815 | W39: =Model!J16 -> 12476.601 | X39: =Model!K16 -> 12913.268 | Y39: =Model!L16 -> 13338.809
P41: Adjusted EBITDA | Q41: =Model!D38 -> 1110.431 | R41: =Model!E38 -> 1253.404 | S41: =Model!F38 -> 1850.993 | T41: =Model!G38 -> 1816.443 | U41: =Model!H38 -> 1885.9221 | V41: =Model!I38 -> 1932.9363 | W41: =Model!J38 -> 2021.2094 | X41: =Model!K38 -> 2104.8627 | Y41: =Model!L38 -> 2174.2258
P42: Free cash flow | Q42: =Model!D155 -> 189.956 | R42: =Model!E155 -> 697.247 | S42: =Model!F155 -> 452.59 | T42: =Model!G155 -> -374.658 | U42: =Model!H155 -> -20.694986 | V42: =Model!I155 -> 137.09579 | W42: =Model!J155 -> 280.45396 | X42: =Model!K155 -> 375.26213 | Y42: =Model!L155 -> 462.03048
P43: Dividends paid to owners | Q43: =-Model!D135 -> 253.012 | R43: =-Model!E135 -> 286.601 | S43: =-Model!F135 -> 449.83 | T43: =-Model!G135 -> 274.84 | U43: =-Model!H135 -> 447.16405 | V43: =-Model!I135 -> 448.00835 | W43: =-Model!J135 -> 448.00835 | X43: =-Model!K135 -> 448.00835 | Y43: =-Model!L135 -> 448.00835
P44: Net profit attributable to owners | Q44: =Model!D70 -> 269.15 | R44: =Model!E70 -> 365.397 | S44: =Model!F70 -> 597.891 | T44: =Model!G70 -> 673.923 | U44: =Model!H70 -> 456.24891 | V44: =Model!I70 -> 375.81229 | W44: =Model!J70 -> 397.53971 | X44: =Model!K70 -> 434.45686 | Y44: =Model!L70 -> 469.71165
P45: Net debt / adjusted EBITDA (x) | Q45: =Model!D221 -> 2.9673523 | R45: =Model!E221 -> 2.2815501 | S45: =Model!F221 -> 2.1359735 | T45: =Model!G221 -> 3.0198355 | U45: =Model!H221 -> 3.5315344 | V45: =Model!I221 -> 3.59621 | W45: =Model!J221 -> 3.5204172 | X45: =Model!K221 -> 3.4182127 | Y45: =Model!L221 -> 3.3085778
P47: Data: scenarios
...

Sheet Outputs
B1: Kofola ČeskoSlovensko | Outputs
B2: CZK m unless stated
B4: Scenario
B5: Active scenario | D5: 1
B7: DCF inputs
B8: WACC | D8: =Inputs!D123 -> 0.065735342
B9: Terminal growth rate | D9: 0.02 | N9: CNB inflation target
B10: Exit multiple (EV / EBITDA) | D10: =Comps!G30 -> 9.2896732
B12: DCF summary
D15: Perpetuity | E15: Exit
B16: CZK m unless stated | D16: growth | E16: multiple
B17: PV of discrete forecast (H2 2026F to 2030F) | C17: CZK m | D17: =Model!L286 -> 2609.0505 | E17: =Model!L325 -> 2609.0505
B18: PV of terminal value | C18: CZK m | D18: =Model!L287 -> 13108.111 | E18: =Model!L326 -> 15159.803
B19: Enterprise value | C19: CZK m | D19: =SUM(D17:D18) -> 15717.161 | E19: =SUM(E17:E18) -> 17768.853
B20: Less: net debt at 30.06.2026 | C20: CZK m | D20: =Model!D292 -> -6441.73 | E20: =Model!D331 -> -6441.73
B21: Less: non-controlling interests | C21: CZK m | D21: =Model!D293 -> -350.207 | E21: =Model!D332 -> -350.207
B22: Plus: equity-accounted investments | C22: CZK m | D22: =Model!D294 -> 390.528 | E22: =Model!D333 -> 390.528
B23: Less: FY2025 dividend unpaid at 30.06.2026 | C23: CZK m | D23: =Model!D295 -> -447.16405 | E23: =Model!D334 -> -447.16405
B24: Equity value | C24: CZK m | D24: =SUM(D19:D23) -> 8868.5881 | E24: =SUM(E19:E23) -> 10920.28
B25: Shares outstanding | C25: m | D25: =SharesOut -> 21.333731 | E25: =SharesOut -> 21.333731
B26: Equity value per share | C26: CZK | D26: =D24/D25 -> 415.70732 | E26: =E24/E25 -> 511.87859
B27: Share price at 30.06.2026 | C27: CZK | D27: =Model!L294 -> 493 | E27: =Model!L333 -> 493
B28: Upside / (downside) | C28: % | D28: =D26/D27-1 -> -0.15678028 | E28: =E26/E27-1 -> 0.03829328
B30: Cross-checks
B31: Terminal value as % of enterprise value | C31: % | D31: =Model!K287 -> 0.83399989 | E31: =Model!K326 -> 0.8531672
B32: Implied EV / 2030F EBITDA | C32: x | D32: =Model!L296 -> 7.7800865 | E32: =D10 -> 9.2896732
B33: Implied perpetuity growth rate | C33: % | D33: =D9 -> 0.02 | E33: =Model!L335 -> 0.025958693
B35: Football field
G38: Base /
B39: Value per share | D39: Low | E39: Range | F39: High | G39: median
B40: DCF (perpetuity growth) | C40: CZK | D40: =MIN(F117:H119) -> 292.45327 | E40: =F40-D40 -> 315.32049 | F40: =MAX(F117:H119) -> 607.77376 | G40: =G118 -> 415.70732
B41: DCF (exit multiple) | C41: CZK | D41: =MIN(F142:H144) -> 420.92545 | E41: =F41-D41 -> 185.55306 | F41: =MAX(F142:H144) -> 606.47851 | G41: =G143 -> 511.87859
B42: Trading comps (EV / EBITDA) | C42: CZK | D42: =Comps!D67 -> 200.30553 | E42: =Comps!E67 -> 431.93028 | F42: =Comps!F67 -> 632.2358 | G42: =Comps!G67 -> 451.57755
B43: Trading comps (P / E) | C43: CZK | D43: =Comps!D68 -> 216.70021 | E43: =Comps!E68 -> 205.20718 | F43: =Comps!F68 -> 421.90739 | G43: =Comps!G68 -> 292.33561
B44: Precedent transactions (EV / EBITDA) | C44: CZK | D44: =Comps!D69 -> 577.18758 | E44: =Comps!E69 -> 408.70861 | F44: =Comps!F69 -> 985.89619 | G44: =Comps!G69 -> 740.66789
B45: 52-week trading range | C45: CZK | D45: =MIN(Dashboard!$Q$62:$Q$311) -> 450 | E45: =F45-D45 -> 96 | F45: =MAX(Dashboard!$Q$62:$Q$311) -> 546 | G45: =Inputs!D113 -> 493 | N45: PSE closing prices 01.07.2025 to 30.06.2026 (Yahoo Finance)
B46: Average of base values (DCF and EV / EBITDA comps) | C46: CZK | G46: =AVERAGE(G40:G42) -> 459.72115
B48: Scenario analysis
B51: Valuation and key metrics
D52: Perpetuity | E52: Exit mult. | F52: Perpetuity | G52: Exit mult. | H52: Adj. EBITDA | I52: Adj. EBITDA | J52: EPS | K52: FCF after | L52: ND / EBITDA
...

Sheet Inputs
B1: Kofola ČeskoSlovensko | Inputs
B2: CZK m unless stated | F2: Scenario | G2: =ScenarioName -> Base case | J2: Model checks | L2: =ModelChecks -> OK
B4: Fiscal year ending 31 December | D4: =Model!D$4 -> 2022 | E4: =Model!E$4 -> 2023 | F4: =Model!F$4 -> 2024 | G4: =Model!G$4 -> 2025 | H4: =Model!H$4 -> 2026 | I4: =Model!I$4 -> 2027 | J4: =Model!J$4 -> 2028 | K4: =Model!K$4 -> 2029 | L4: =Model!L$4 -> 2030
B5: Period end | D5: =Model!D$5 -> 44926 | E5: =Model!E$5 -> 45291 | F5: =Model!F$5 -> 45657 | G5: =Model!G$5 -> 46022 | H5: =Model!H$5 -> 46387 | I5: =Model!I$5 -> 46752 | J5: =Model!J$5 -> 47118 | K5: =Model!K$5 -> 47483 | L5: =Model!L$5 -> 47848
B6: Actual / forecast | D6: =Model!D$6 -> A | E6: =Model!E$6 -> A | F6: =Model!F$6 -> A | G6: =Model!G$6 -> A | H6: =Model!H$6 -> F | I6: =Model!I$6 -> F | J6: =Model!J$6 -> F | K6: =Model!K$6 -> F | L6: =Model!L$6 -> F
B8: General
B9: First historical year | D9: 2022
B10: Last actual year | D10: 2025
B11: Valuation date | D11: 46203
B12: Czech corporate income tax rate | D12: 0.21
B13: Shares issued | C13: m | D13: 22.291948 | N13: H1 2026 report, note 4.14
B14: Treasury shares held by RADENSKA | C14: m | D14: 0.958217 | N14: H1 2026 report
B15: Shares outstanding at valuation date | C15: m | D15: =D13-D14 -> 21.333731
B17: Scenario drivers
B18: % y/y unless stated | D18: =Model!D$4 -> 2022 | E18: =Model!E$4 -> 2023 | F18: =Model!F$4 -> 2024 | G18: =Model!G$4 -> 2025 | H18: =Model!H$4 -> 2026 | I18: =Model!I$4 -> 2027 | J18: =Model!J$4 -> 2028 | K18: =Model!K$4 -> 2029 | L18: =Model!L$4 -> 2030
B19: Active scenario
B21: Revenue growth by segment
B22: CzechoSlovakia | E22: =Model!E20 -> 0.10091836 | F22: =Model!F20 -> 0.11099327 | G22: =Model!G20 -> -0.067431895
B23: Base | H23: 0.1 | I23: 0.04 | J23: 0.035 | K23: 0.03 | L23: 0.03
B24: Upside | H24: 0.12 | I24: 0.05 | J24: 0.045 | K24: 0.04 | L24: 0.035
B25: Downside | H25: 0.07 | I25: 0.02 | J25: -0.06 | K25: 0.04 | L25: 0.02
B26: Live case | H26: =CHOOSE(Scenario,H23,H24,H25) -> 0.1 | I26: =CHOOSE(Scenario,I23,I24,I25) -> 0.04 | J26: =CHOOSE(Scenario,J23,J24,J25) -> 0.035 | K26: =CHOOSE(Scenario,K23,K24,K25) -> 0.03 | L26: =CHOOSE(Scenario,L23,L24,L25) -> 0.03
B28: Adriatic | E28: =Model!E21 -> 0.071744054 | F28: =Model!F21 -> 0.11108383 | G28: =Model!G21 -> -0.018417013
B29: Base | H29: 0.02 | I29: 0.03 | J29: 0.03 | K29: 0.03 | L29: 0.025
B30: Upside | H30: 0.035 | I30: 0.04 | J30: 0.04 | K30: 0.035 | L30: 0.03
B31: Downside | H31: 0 | I31: 0.01 | J31: 0.01 | K31: 0.015 | L31: 0.015
B32: Live case | H32: =CHOOSE(Scenario,H29,H30,H31) -> 0.02 | I32: =CHOOSE(Scenario,I29,I30,I31) -> 0.03 | J32: =CHOOSE(Scenario,J29,J30,J31) -> 0.03 | K32: =CHOOSE(Scenario,K29,K30,K31) -> 0.03 | L32: =CHOOSE(Scenario,L29,L30,L31) -> 0.025
B34: Fresh & Herbs | E34: =Model!E22 -> 0.17114711 | F34: =Model!F22 -> 0.19827776 | G34: =Model!G22 -> 0.15463543
B35: Base | H35: 0.18 | I35: 0.1 | J35: 0.08 | K35: 0.07 | L35: 0.06
B36: Upside | H36: 0.22 | I36: 0.13 | J36: 0.1 | K36: 0.08 | L36: 0.07
B37: Downside | H37: 0.14 | I37: 0.06 | J37: 0.05 | K37: 0.04 | L37: 0.04
B38: Live case | H38: =CHOOSE(Scenario,H35,H36,H37) -> 0.18 | I38: =CHOOSE(Scenario,I35,I36,I37) -> 0.1 | J38: =CHOOSE(Scenario,J35,J36,J37) -> 0.08 | K38: =CHOOSE(Scenario,K35,K36,K37) -> 0.07 | L38: =CHOOSE(Scenario,L35,L36,L37) -> 0.06
B40: Beers & Ciders | E40: =Model!E23 -> n.m. | F40: =Model!F23 -> n.m. | G40: =Model!G23 -> 0.056352049
B41: Base | H41: -0.04 | I41: 0.015 | J41: 0.02 | K41: 0.02 | L41: 0.02
B42: Upside | H42: -0.02 | I42: 0.03 | J42: 0.03 | K42: 0.03 | L42: 0.025
B43: Downside | H43: -0.07 | I43: -0.01 | J43: 0 | K43: 0 | L43: 0.005
B44: Live case | H44: =CHOOSE(Scenario,H41,H42,H43) -> -0.04 | I44: =CHOOSE(Scenario,I41,I42,I43) -> 0.015 | J44: =CHOOSE(Scenario,J41,J42,J43) -> 0.02 | K44: =CHOOSE(Scenario,K41,K42,K43) -> 0.02 | L44: =CHOOSE(Scenario,L41,L42,L43) -> 0.02
B46: Other revenue inputs
B47: Consolidation adjustments (% of segment revenue) | D47: =Model!D25 -> -0.018801087 | E47: =Model!E25 -> -0.018790005 | F47: =Model!F25 -> -0.021865054 | G47: =Model!G25 -> -0.030687617 | H47: -0.04 | I47: -0.04 | J47: -0.04 | K47: -0.04 | L47: -0.04
B50: Cost drivers (% of revenue)
...

Sheet Model
B1: Kofola ČeskoSlovensko | Model
B2: CZK m unless stated | F2: Scenario | G2: =ScenarioName -> Base case | J2: Model checks | L2: =ModelChecks -> OK
B4: Fiscal year ending 31 December | D4: =FirstYear -> 2022 | E4: =D4+1 -> 2023 | F4: =E4+1 -> 2024 | G4: =F4+1 -> 2025 | H4: =G4+1 -> 2026 | I4: =H4+1 -> 2027 | J4: =I4+1 -> 2028 | K4: =J4+1 -> 2029 | L4: =K4+1 -> 2030
B5: Period end | D5: =DATE(D4,12,31) -> 44926 | E5: =DATE(E4,12,31) -> 45291 | F5: =DATE(F4,12,31) -> 45657 | G5: =DATE(G4,12,31) -> 46022 | H5: =DATE(H4,12,31) -> 46387 | I5: =DATE(I4,12,31) -> 46752 | J5: =DATE(J4,12,31) -> 47118 | K5: =DATE(K4,12,31) -> 47483 | L5: =DATE(L4,12,31) -> 47848
B6: Actual / forecast | D6: =IF(D$4<=LastActual,"A","F") -> A | E6: =IF(E$4<=LastActual,"A","F") -> A | F6: =IF(F$4<=LastActual,"A","F") -> A | G6: =IF(G$4<=LastActual,"A","F") -> A | H6: =IF(H$4<=LastActual,"A","F") -> F | I6: =IF(I$4<=LastActual,"A","F") -> F | J6: =IF(J$4<=LastActual,"A","F") -> F | K6: =IF(K$4<=LastActual,"A","F") -> F | L6: =IF(L$4<=LastActual,"A","F") -> F
B8: Revenue schedule
B9: CZK m | D9: =D$4 -> 2022 | E9: =E$4 -> 2023 | F9: =F$4 -> 2024 | G9: =G$4 -> 2025 | H9: =H$4 -> 2026 | I9: =I$4 -> 2027 | J9: =J$4 -> 2028 | K9: =K$4 -> 2029 | L9: =L$4 -> 2030
B10: Segment revenue, incl. inter-segment sales
B11: CzechoSlovakia | D11: =Hist!D149 -> 5735.854 | E11: =Hist!E149 -> 6314.707 | F11: =Hist!F149 -> 7015.597 | G11: =Hist!G149 -> 6542.522 | H11: =G11*(1+Inputs!H26) -> 7196.7742 | I11: =H11*(1+Inputs!I26) -> 7484.6452 | J11: =I11*(1+Inputs!J26) -> 7746.6077 | K11: =J11*(1+Inputs!K26) -> 7979.006 | L11: =K11*(1+Inputs!L26) -> 8218.3762
B12: Adriatic | D12: =Hist!D150 -> 1413.483 | E12: =Hist!E150 -> 1514.892 | F12: =Hist!F150 -> 1683.172 | G12: =Hist!G150 -> 1652.173 | H12: =G12*(1+Inputs!H32) -> 1685.2165 | I12: =H12*(1+Inputs!I32) -> 1735.773 | J12: =I12*(1+Inputs!J32) -> 1787.8461 | K12: =J12*(1+Inputs!K32) -> 1841.4815 | L12: =K12*(1+Inputs!L32) -> 1887.5186
B13: Fresh & Herbs | D13: =Hist!D151 -> 876.848 | E13: =Hist!E151 -> 1026.918 | F13: =Hist!F151 -> 1230.533 | G13: =Hist!G151 -> 1420.817 | H13: =G13*(1+Inputs!H38) -> 1676.5641 | I13: =H13*(1+Inputs!I38) -> 1844.2205 | J13: =I13*(1+Inputs!J38) -> 1991.7581 | K13: =J13*(1+Inputs!K38) -> 2131.1812 | L13: =K13*(1+Inputs!L38) -> 2259.052
B14: Beers & Ciders | D14: =Hist!D152 -> 0 | E14: =Hist!E152 -> 0 | F14: =Hist!F152 -> 1400.375 | G14: =Hist!G152 -> 1479.289 | H14: =G14*(1+Inputs!H44) -> 1420.1174 | I14: =H14*(1+Inputs!I44) -> 1441.4192 | J14: =I14*(1+Inputs!J44) -> 1470.2476 | K14: =J14*(1+Inputs!K44) -> 1499.6525 | L14: =K14*(1+Inputs!L44) -> 1529.6456
B15: Consolidation adjustments | D15: =Hist!D153 -> -150.901 | E15: =Hist!E153 -> -166.414 | F15: =Hist!F153 -> -247.724 | G15: =Hist!G153 -> -340.473 | H15: =Inputs!H47*SUM(H11:H14) -> -479.14689 | I15: =Inputs!I47*SUM(I11:I14) -> -500.24231 | J15: =Inputs!J47*SUM(J11:J14) -> -519.85838 | K15: =Inputs!K47*SUM(K11:K14) -> -538.05285 | L15: =Inputs!L47*SUM(L11:L14) -> -555.78369
B16: Revenue | D16: =SUM(D11:D15) -> 7875.284 | E16: =SUM(E11:E15) -> 8690.103 | F16: =SUM(F11:F15) -> 11081.953 | G16: =SUM(G11:G15) -> 10754.328 | H16: =SUM(H11:H15) -> 11499.525 | I16: =SUM(I11:I15) -> 12005.815 | J16: =SUM(J11:J15) -> 12476.601 | K16: =SUM(K11:K15) -> 12913.268 | L16: =SUM(L11:L15) -> 13338.809
B18: Implied H2 2026 revenue growth | H18: =(H16-Hist!E301)/(G16-Hist!D301)-1 -> 0.040113924
B19: Growth y/y
B20: CzechoSlovakia | E20: =IF(D11=0,"n.m.",E11/D11-1) -> 0.10091836 | F20: =IF(E11=0,"n.m.",F11/E11-1) -> 0.11099327 | G20: =IF(F11=0,"n.m.",G11/F11-1) -> -0.067431895 | H20: =IF(G11=0,"n.m.",H11/G11-1) -> 0.1 | I20: =IF(H11=0,"n.m.",I11/H11-1) -> 0.04 | J20: =IF(I11=0,"n.m.",J11/I11-1) -> 0.035 | K20: =IF(J11=0,"n.m.",K11/J11-1) -> 0.03 | L20: =IF(K11=0,"n.m.",L11/K11-1) -> 0.03
B21: Adriatic | E21: =IF(D12=0,"n.m.",E12/D12-1) -> 0.071744054 | F21: =IF(E12=0,"n.m.",F12/E12-1) -> 0.11108383 | G21: =IF(F12=0,"n.m.",G12/F12-1) -> -0.018417013 | H21: =IF(G12=0,"n.m.",H12/G12-1) -> 0.02 | I21: =IF(H12=0,"n.m.",I12/H12-1) -> 0.03 | J21: =IF(I12=0,"n.m.",J12/I12-1) -> 0.03 | K21: =IF(J12=0,"n.m.",K12/J12-1) -> 0.03 | L21: =IF(K12=0,"n.m.",L12/K12-1) -> 0.025
B22: Fresh & Herbs | E22: =IF(D13=0,"n.m.",E13/D13-1) -> 0.17114711 | F22: =IF(E13=0,"n.m.",F13/E13-1) -> 0.19827776 | G22: =IF(F13=0,"n.m.",G13/F13-1) -> 0.15463543 | H22: =IF(G13=0,"n.m.",H13/G13-1) -> 0.18 | I22: =IF(H13=0,"n.m.",I13/H13-1) -> 0.1 | J22: =IF(I13=0,"n.m.",J13/I13-1) -> 0.08 | K22: =IF(J13=0,"n.m.",K13/J13-1) -> 0.07 | L22: =IF(K13=0,"n.m.",L13/K13-1) -> 0.06
B23: Beers & Ciders | E23: =IF(D14=0,"n.m.",E14/D14-1) -> n.m. | F23: =IF(E14=0,"n.m.",F14/E14-1) -> n.m. | G23: =IF(F14=0,"n.m.",G14/F14-1) -> 0.056352049 | H23: =IF(G14=0,"n.m.",H14/G14-1) -> -0.04 | I23: =IF(H14=0,"n.m.",I14/H14-1) -> 0.015 | J23: =IF(I14=0,"n.m.",J14/I14-1) -> 0.02 | K23: =IF(J14=0,"n.m.",K14/J14-1) -> 0.02 | L23: =IF(K14=0,"n.m.",L14/K14-1) -> 0.02
B24: Revenue | E24: =IF(D16=0,"n.m.",E16/D16-1) -> 0.10346535 | F24: =IF(E16=0,"n.m.",F16/E16-1) -> 0.27523839 | G24: =IF(F16=0,"n.m.",G16/F16-1) -> -0.029563832 | H24: =IF(G16=0,"n.m.",H16/G16-1) -> 0.069292779 | I24: =IF(H16=0,"n.m.",I16/H16-1) -> 0.044027053 | J24: =IF(I16=0,"n.m.",J16/I16-1) -> 0.03921314 | K24: =IF(J16=0,"n.m.",K16/J16-1) -> 0.034998888 | L24: =IF(K16=0,"n.m.",L16/K16-1) -> 0.032953725
B25: Consolidation adjustments (% of segment revenue) | D25: =D15/SUM(D11:D14) -> -0.018801087 | E25: =E15/SUM(E11:E14) -> -0.018790005 | F25: =F15/SUM(F11:F14) -> -0.021865054 | G25: =G15/SUM(G11:G14) -> -0.030687617 | H25: =H15/SUM(H11:H14) -> -0.04 | I25: =I15/SUM(I11:I14) -> -0.04 | J25: =J15/SUM(J11:J14) -> -0.04 | K25: =K15/SUM(K11:K14) -> -0.04 | L25: =L15/SUM(L11:L14) -> -0.04
B27: Cost schedule (by nature)
B28: CZK m | D28: =D$4 -> 2022 | E28: =E$4 -> 2023 | F28: =F$4 -> 2024 | G28: =G$4 -> 2025 | H28: =H$4 -> 2026 | I28: =I$4 -> 2027 | J28: =J$4 -> 2028 | K28: =K$4 -> 2029 | L28: =L$4 -> 2030
B29: Revenue | D29: =D16 -> 7875.284 | E29: =E16 -> 8690.103 | F29: =F16 -> 11081.953 | G29: =G16 -> 10754.328 | H29: =H16 -> 11499.525 | I29: =I16 -> 12005.815 | J29: =J16 -> 12476.601 | K29: =K16 -> 12913.268 | L29: =L16 -> 13338.809
B30: Materials, energy and cost of goods sold | D30: =-Hist!D220 -> -3792.347 | E30: =-Hist!E220 -> -3892.998 | F30: =-Hist!F220 -> -4687.851 | G30: =-Hist!G220 -> -4284.321 | H30: =-H$29*Inputs!H55 -> -4588.3106 | I30: =-I$29*Inputs!I55 -> -4838.3436 | J30: =-J$29*Inputs!J55 -> -5028.0703 | K30: =-K$29*Inputs!K55 -> -5204.0472 | L30: =-L$29*Inputs!L55 -> -5375.5399
B31: Employee benefits | D31: =-Hist!D219 -> -1509.911 | E31: =-Hist!E219 -> -1817.851 | F31: =-Hist!F219 -> -2340.944 | G31: =-Hist!G219 -> -2302.736 | H31: =-H$29*Inputs!H61 -> -2564.3941 | I31: =-I$29*Inputs!I61 -> -2665.291 | J31: =-J$29*Inputs!J61 -> -2757.3289 | K31: =-K$29*Inputs!K61 -> -2840.919 | L31: =-L$29*Inputs!L61 -> -2934.5379
B32: Services | D32: =-Hist!D221 -> -1373.224 | E32: =-Hist!E221 -> -1528.977 | F32: =-Hist!F221 -> -2027.972 | G32: =-Hist!G221 -> -2031.106 | H32: =-H$29*Inputs!H64 -> -2184.9098 | I32: =-I$29*Inputs!I64 -> -2281.1049 | J32: =-J$29*Inputs!J64 -> -2370.5542 | K32: =-K$29*Inputs!K64 -> -2453.521 | L32: =-L$29*Inputs!L64 -> -2534.3736
B33: Other operating costs | D33: =-SUM(Hist!D222:D228) -> -107.233 | E33: =-SUM(Hist!E222:E228) -> -223.268 | F33: =-SUM(Hist!F222:F228) -> -213.165 | G33: =-SUM(Hist!G222:G228) -> -259.456 | H33: =-H$29*Inputs!H65 -> -275.98861 | I33: =-I$29*Inputs!I65 -> -288.13957 | J33: =-J$29*Inputs!J65 -> -299.43843 | K33: =-K$29*Inputs!K65 -> -309.91844 | L33: =-L$29*Inputs!L65 -> -320.13141
B34: Other operating income | D34: =Hist!D12 -> 47.858 | E34: =Hist!E12 -> 89.917 | F34: =Hist!F12 -> 271.889 | G34: =Hist!G12 -> 152.164 | H34: =H$29*Inputs!H66 -> 0 | I34: =I$29*Inputs!I66 -> 0 | J34: =J$29*Inputs!J66 -> 0 | K34: =K$29*Inputs!K66 -> 0 | L34: =L$29*Inputs!L66 -> 0
B35: Other operating expenses (excl. D&A) | D35: =Hist!D13-Hist!D230 -> -71.691 | E35: =Hist!E13-Hist!E230 -> -29.302 | F35: =Hist!F13-Hist!F230 -> -166.779 | G35: =Hist!G13-Hist!G230 -> -103.646 | H35: =0 -> 0 | I35: =0 -> 0 | J35: =0 -> 0 | K35: =0 -> 0 | L35: =0 -> 0
B36: EBITDA | D36: =SUM(D29:D35) -> 1068.736 | E36: =SUM(E29:E35) -> 1287.624 | F36: =SUM(F29:F35) -> 1917.131 | G36: =SUM(G29:G35) -> 1925.227 | H36: =SUM(H29:H35) -> 1885.9221 | I36: =SUM(I29:I35) -> 1932.9363 | J36: =SUM(J29:J35) -> 2021.2094 | K36: =SUM(K29:K35) -> 2104.8627 | L36: =SUM(L29:L35) -> 2174.2258
B37: One-off items | D37: =Hist!D34 -> 41.695 | E37: =Hist!E34 -> -34.22 | F37: =Hist!F34 -> -66.138 | G37: =Hist!G34 -> -108.784 | H37: =0 -> 0 | I37: =0 -> 0 | J37: =0 -> 0 | K37: =0 -> 0 | L37: =0 -> 0
B38: Adjusted EBITDA | D38: =D36+D37 -> 1110.431 | E38: =E36+E37 -> 1253.404 | F38: =F36+F37 -> 1850.993 | G38: =G36+G37 -> 1816.443 | H38: =H36+H37 -> 1885.9221 | I38: =I36+I37 -> 1932.9363 | J38: =J36+J37 -> 2021.2094 | K38: =K36+K37 -> 2104.8627 | L38: =L36+L37 -> 2174.2258
B39: Check: EBITDA vs reported EBIT + D&A | D39: =ROUND(D36-(Hist!D36+Hist!D94),1) -> 0 | E39: =ROUND(E36-(Hist!E36+Hist!E94),1) -> 0 | F39: =ROUND(F36-(Hist!F36+Hist!F94),1) -> 0 | G39: =ROUND(G36-(Hist!G36+Hist!G94),1) -> 0
B40: Check: FY2026F adjusted EBITDA within guidance (CZK 1.8 to 1.9bn) | H40: =IF(AND(H38>=GuideLow,H38<=GuideHigh),0,1) -> 0
B41: Implied H2 2026 adjusted EBITDA growth | H41: =(H38-Hist!E323)/(G38-Hist!D323)-1 -> -0.033561155
B42: Cost ratios and margins (% of revenue)
B43: Materials, energy and COGS | D43: =-D30/D29 -> 0.48155051 | E43: =-E30/E29 -> 0.44798065 | F43: =-F30/F29 -> 0.42301668 | G43: =-G30/G29 -> 0.3983811 | H43: =-H30/H29 -> 0.399 | I43: =-I30/I29 -> 0.403 | J43: =-J30/J29 -> 0.403 | K43: =-K30/K29 -> 0.403 | L43: =-L30/L29 -> 0.403
B44: Employee benefits | D44: =-D31/D29 -> 0.19172782 | E44: =-E31/E29 -> 0.20918636 | F44: =-F31/F29 -> 0.2112393 | G44: =-G31/G29 -> 0.21412179 | H44: =-H31/H29 -> 0.223 | I44: =-I31/I29 -> 0.222 | J44: =-J31/J29 -> 0.221 | K44: =-K31/K29 -> 0.22 | L44: =-L31/L29 -> 0.22
...

Sheet Comps
B1: Kofola ČeskoSlovensko | Trading comparables
B2: Peers in their own reporting currency (millions), Kofola in CZK m. Valuation date 30.06.2026.
B4: Peer data at 30.06.2026
B5: Company H1 2026 reports, closing prices on 30.06.2026
D7: Share | E7: Shares | F7: Net | I7: LTM | J7: LTM adj. | K7: LTM net | L7: LTM
B8: Company | C8: Ccy | D8: price | E8: outstanding | F8: debt | G8: NCI | H8: Associates | I8: revenue | J8: EBITDA | K8: profit | L8: ends
D9: per share | E9: m | F9: m | G9: m | H9: m | I9: m | J9: m | K9: m
B10: Coca-Cola HBC | C10: EUR | D10: 57 | E10: 364.03068 | F10: 1413.6 | G10: 96.8 | H10: 0 | I10: 12213.6 | J10: 1942.1 | K10: 1063.1 | L10: Jul-26
B11: A.G. Barr | C11: GBP | D11: 6.33 | E11: 110.84682 | F11: 55.4 | G11: 6.6 | H11: 0 | I11: 456.6 | J11: 79.4 | K11: 49.3 | L11: Aug-26
B12: Royal Unibrew | C12: DKK | D12: 431.4 | E12: 47.827612 | F12: 6610 | G12: 0 | H12: 0 | I12: 15816 | J12: 3040 | K12: 1610 | L12: Jun-26
B13: Olvi | C13: EUR | D13: 32 | E13: 20.635045 | F13: 62.694 | G13: 2.851 | H13: 0.983 | I13: 709.702 | J13: 115.641 | K13: 65.868 | L13: Jun-26
B14: Shown, not in the statistics
B15: Fever-Tree | C15: GBP | D15: 8.125 | E15: 113.11196 | F15: -64.2 | G15: 0 | H15: 0 | I15: 345.8 | J15: 44.1 | K15: 25.2 | L15: Jun-26
B17: Target
B18: Kofola ČeskoSlovensko | C18: CZK | D18: =Inputs!D113 -> 493 | E18: =SharesOut -> 21.333731 | F18: =Hist!E371 -> 6441.73 | G18: =Hist!E351 -> 350.207 | H18: =Hist!E332 -> 390.528 | I18: =Hist!F301 -> 11271.289 | J18: =Hist!F323-Inputs!D127 -> 1774.272 | K18: =Hist!F315+Hist!F322*(1-TaxRate)-Inputs!D127*(1-TaxRate) -> 461.1532 | L18: Jun-26
B20: Trading multiples (LTM)
D22: Market | E22: Enterprise | F22: EV / | G22: EV / | I22: EBITDA | J22: Net debt /
B23: Company | C23: Ccy | D23: cap | E23: value | F23: revenue | G23: EBITDA | H23: P / E | I23: margin | J23: EBITDA
D24: m | E24: m | F24: x | G24: x | H24: x | I24: % | J24: x
B25: Coca-Cola HBC | C25: EUR | D25: =D10*E10 -> 20749.749 | E25: =D25+F10+G10-H10 -> 22260.149 | F25: =E25/I10 -> 1.8225706 | G25: =E25/J10 -> 11.461896 | H25: =D25/K10 -> 19.518153 | I25: =J10/I10 -> 0.15901127 | J25: =F10/J10 -> 0.72787189
B26: A.G. Barr | C26: GBP | D26: =D11*E11 -> 701.66035 | E26: =D26+F11+G11-H11 -> 763.66035 | F26: =E26/I11 -> 1.6724931 | G26: =E26/J11 -> 9.6178885 | H26: =D26/K11 -> 14.232461 | I26: =J11/I11 -> 0.173894 | J26: =F11/J11 -> 0.697733
B27: Royal Unibrew | C27: DKK | D27: =D12*E12 -> 20632.832 | E27: =D27+F12+G12-H12 -> 27242.832 | F27: =E27/I12 -> 1.7224856 | G27: =E27/J12 -> 8.9614578 | H27: =D27/K12 -> 12.815423 | I27: =J12/I12 -> 0.19221042 | J27: =F12/J12 -> 2.1743421
B28: Olvi | C28: EUR | D28: =D13*E13 -> 660.32144 | E28: =D28+F13+G13-H13 -> 724.88344 | F28: =E28/I13 -> 1.0213913 | G28: =E28/J13 -> 6.2683948 | H28: =D28/K13 -> 10.02492 | I28: =J13/I13 -> 0.16294304 | J28: =F13/J13 -> 0.54214336
B29: Average | F29: =AVERAGE(F25:F28) -> 1.5597351 | G29: =AVERAGE(G25:G28) -> 9.0774093 | H29: =AVERAGE(H25:H28) -> 14.14774 | I29: =AVERAGE(I25:I28) -> 0.17201468 | J29: =AVERAGE(J25:J28) -> 1.0355226
B30: Median | F30: =MEDIAN(F25:F28) -> 1.6974893 | G30: =MEDIAN(G25:G28) -> 9.2896732 | H30: =MEDIAN(H25:H28) -> 13.523942 | I30: =MEDIAN(I25:I28) -> 0.16841852 | J30: =MEDIAN(J25:J28) -> 0.71280244
B31: Maximum | F31: =MAX(F25:F28) -> 1.8225706 | G31: =MAX(G25:G28) -> 11.461896 | H31: =MAX(H25:H28) -> 19.518153 | I31: =MAX(I25:I28) -> 0.19221042 | J31: =MAX(J25:J28) -> 2.1743421
B32: Minimum | F32: =MIN(F25:F28) -> 1.0213913 | G32: =MIN(G25:G28) -> 6.2683948 | H32: =MIN(H25:H28) -> 10.02492 | I32: =MIN(I25:I28) -> 0.15901127 | J32: =MIN(J25:J28) -> 0.54214336
B34: Shown, not in the statistics
B35: Fever-Tree | C35: GBP | D35: =D15*E15 -> 919.03464 | E35: =D35+F15+G15-H15 -> 854.83464 | F35: =E35/I15 -> 2.4720493 | G35: =E35/J15 -> 19.384005 | H35: =D35/K15 -> 36.469629 | I35: =J15/I15 -> 0.12753036 | J35: =F15/J15 -> -1.4557823
B37: Target at the 30.06.2026 share price
B38: Kofola ČeskoSlovensko | C38: CZK | D38: =D18*E18 -> 10517.529 | E38: =D38+F18+G18-H18-Model!D295 -> 17366.102 | F38: =E38/I18 -> 1.5407379 | G38: =E38/J18 -> 9.787734 | H38: =D38/K18 -> 22.807018 | I38: =J18/I18 -> 0.15741518 | J38: =F18/J18 -> 3.6306327
B40: Implied value per share from peer multiples
B42: CZK m unless stated | D42: Minimum | E42: Average | F42: Median | G42: Maximum
B43: EV / LTM EBITDA
B44: Peer EV / EBITDA | C44: x | D44: =G32 -> 6.2683948 | E44: =G29 -> 9.0774093 | F44: =G30 -> 9.2896732 | G44: =G31 -> 11.461896
B45: Kofola LTM adjusted EBITDA, bonus-normalised | C45: CZK m | D45: =$J$18 -> 1774.272 | E45: =$J$18 -> 1774.272 | F45: =$J$18 -> 1774.272 | G45: =$J$18 -> 1774.272
B46: Implied enterprise value | C46: CZK m | D46: =D44*D45 -> 11121.837 | E46: =E44*E45 -> 16105.793 | F46: =F44*F45 -> 16482.407 | G46: =G44*G45 -> 20336.522
B47: Less: net debt at 30.06.2026 | C47: CZK m | D47: =Model!$D$292 -> -6441.73 | E47: =Model!$D$292 -> -6441.73 | F47: =Model!$D$292 -> -6441.73 | G47: =Model!$D$292 -> -6441.73
B48: Less: non-controlling interests | C48: CZK m | D48: =Model!$D$293 -> -350.207 | E48: =Model!$D$293 -> -350.207 | F48: =Model!$D$293 -> -350.207 | G48: =Model!$D$293 -> -350.207
B49: Plus: equity-accounted investments | C49: CZK m | D49: =Model!$D$294 -> 390.528 | E49: =Model!$D$294 -> 390.528 | F49: =Model!$D$294 -> 390.528 | G49: =Model!$D$294 -> 390.528
...

Sheet Hist
B1: Kofola ČeskoSlovensko | Historical data
B2: CZK m unless stated
B4: CZK m | D4: 2022 | E4: 2023 | F4: 2024 | G4: 2025 | H4: Source / note
B6: Income statement (as reported)
B7: Revenue | D7: 7875.284 | E7: 8690.103 | F7: 11081.953 | G7: 10754.328 | H7: XBRL (ESEF) primary statements: FY2024-25 from AR2025, FY2023 from AR2024, FY2022 from AR2023
B8: Cost of sales | D8: -4564.018 | E8: -4802.651 | F8: -6037.14 | G8: -5675
B9: Gross profit | D9: 3311.266 | E9: 3887.452 | F9: 5044.813 | G9: 5079.328
B10: Distribution, sales and marketing expenses | D10: -2329.973 | E10: -2487.765 | F10: -3201.001 | G10: -3356.442
B11: Administrative expenses | D11: -466.509 | E11: -707.052 | F11: -705.866 | G11: -606.82
B12: Other operating income | D12: 47.858 | E12: 89.917 | F12: 271.889 | G12: 152.164
B13: Other operating expenses | D13: -80.002 | E13: -35.349 | F13: -166.779 | G13: -103.646
B14: Operating profit (EBIT) | D14: 482.64 | E14: 747.203 | F14: 1243.056 | G14: 1164.584
B15: Finance income | D15: 158.282 | E15: 34.256 | F15: 46.197 | G15: 84.532
B16: Finance costs | D16: -241.078 | E16: -295.532 | F16: -361.47 | G16: -314.448
B17: Share of profit/(loss) of equity-accounted investees | D17: 0 | E17: -3.985 | F17: -0.482 | G17: -1.758
B18: Profit before tax | D18: 399.844 | E18: 481.942 | F18: 927.301 | G18: 932.91
B19: Income tax expense | D19: -135.925 | E19: -112.965 | F19: -274.149 | G19: -251.321
... B22: attributable to non-controlling interests | D22: -5.231 | E22: 3.58 | F22: 55.26 | G22: 7.665
B24: Per share
B25: Basic EPS (CZK) | D25: 12.07 | E25: 16.39 | F25: 26.82 | G25: 30.23 | H25: XBRL (ESEF) primary statements: FY2024-25 from AR2025, FY2023 from AR2024, FY2022 from AR2023
B26: Cash dividend per share paid in the year (CZK) | D26: 11.3 | E26: 13.5 | F26: 21 | G26: 13.5 | H26: AR equity notes
B27: Total dividend per share declared for the fiscal year (CZK) | D27: 13.5 | E27: 13.5 | F27: 21 | G27: 21 | H27: AR equity notes, AGM of 17.06.2026
B28: Shares issued (m) | D28: 22.291948 | E28: 22.291948 | F28: 22.291948 | G28: 22.291948 | H28: H1 2026 report, note 4.14
B29: Treasury shares held by RADENSKA + own shares (m) | D29: 1.062236 | E29: 1.062236 | F29: 1.025266 | G29: 0.998422 | H29: AR2023 / AR2025 equity notes
B30: Shares outstanding, year end (m) | D30: 21.229712 | E30: 21.229712 | F30: 21.266682 | G30: 21.293526
B31: Memo: EBITDA as defined by Kofola
B32: Depreciation and amortisation | D32: 586.096 | E32: 540.421 | F32: 674.076 | G32: 760.644 | H32: Cash flow statement
B33: EBITDA (reported = EBIT + D&A) | D33: 1068.736 | E33: 1287.624 | F33: 1917.132 | G33: 1925.228
B34: One-off items (EBITDA impact) | D34: 41.695 | E34: -34.22 | F34: -66.138 | G34: -108.784 | H34: Segment note, AR capital management note
B35: Adjusted EBITDA | D35: 1110.431 | E35: 1253.404 | F35: 1850.994 | G35: 1816.444
B36: Reported EBIT (source) | D36: 482.64 | E36: 747.203 | F36: 1243.056 | G36: 1164.584 | H36: Segment notes, total column
B37: Reported net profit (source) | D37: 263.919 | E37: 368.977 | F37: 653.152 | G37: 681.589 | H37: Segment notes, total column
B39: Balance sheet (as reported), 31 December
B40: Non-current assets
B41: Property, plant and equipment (incl. right-of-use) | D41: 3098.477 | E41: 3113.262 | F41: 4410.318 | G41: 5267.049 | H41: XBRL (ESEF) primary statements: FY2024-25 from AR2025, FY2023 from AR2024, FY2022 from AR2023
B42: Investment property | E42: 0 | F42: 31.76 | G42: 32.654
B43: Goodwill | D43: 647.969 | E43: 662.318 | F43: 780.942 | G43: 1053.883
B44: Intangible assets | D44: 1177.692 | E44: 1159.796 | F44: 1668.805 | G44: 1710.093
B45: Equity-accounted investments | D45: 0 | E45: 75.696 | F45: 190.58 | G45: 188.721
B46: Other non-current receivables | D46: 164.792 | E46: 80.569 | F46: 109.585 | G46: 135.33
...
